Workbook
Name CostCentre_Name: '[3]Config panel'!$A$2:$A$32
Name CostCentre_Name: '[1]Config panel'!$A$2:$A$32
Name Fund_Name: '[3]Config panel'!$G$2:$G$21
Name Fund_Name: '[1]Config panel'!$G$2:$G$21
Name RevenueCat_Value: '[3]List of accts-SpendCat CT'!$A$118:$E$119
Name RevenueCat_Value: '[1]List of accts-SpendCat CT'!$A$118:$E$119
Name Spend_Cat_Value: '[3]List of accts-SpendCat CT'!$A$1:$E$116
Name Spend_Cat_Value: '[1]List of accts-SpendCat CT'!$A$1:$E$116
Name SpendCAT_Desc_CAPEX: '[3]List of accts-SpendCat CT'!$A$3:$A$14
Name SpendCAT_Desc_CAPEX: '[1]List of accts-SpendCat CT'!$A$3:$A$14
Name SpendCAT_Desc_EOM: '[3]List of accts-SpendCat CT'!$A$19:$A$21
Name SpendCAT_Desc_EOM: '[1]List of accts-SpendCat CT'!$A$19:$A$21
Name SpendCAT_Desc_OOE: '[3]List of accts-SpendCat CT'!$A$25:$A$113
Name SpendCAT_Desc_OOE: '[1]List of accts-SpendCat CT'!$A$25:$A$113
Name WD_Dept_ID: '[3]Config panel'!#REF!
Name WD_Dept_ID: '[1]Config panel'!#REF!
Name WD_Fund_ID: '[3]Config panel'!$G$2:$H$21
Name WD_Fund_ID: '[1]Config panel'!$G$2:$H$21

Sheet Overview
A1: NP - Grant Management - Proposal Template ( February ) 3.1
A3: Section 1 - Overview
A5: GRANT DETAILS
A7: Grant Call | B7: RIE2030 1st Decentralised GAP Fund (DGF)
A8: Grant Type | B8: NP Translational Research Grant
A9: Proposal ID | B9: NP-2026-DGF-01-001 | D9: Please obtain a proposal ID from TDI.
A11: PROPOSAL DETAILS
A13: Proposal Title | B13: Automotive Battery Thermal Runaway Prediction
A14: Total Project Value ($) | B14: =#REF! -> #REF! | C14: Auto populate from Section 2 - Budget
A15: Project Duration ( Months ) | B15: 18
A16: RIE2025 - Domains | B16: Urban Solutions and Sustainability
A18: PRINCIPAL INVESTIGATOR & CO-PRINCIPAL INVESTIGATOR
A20: WD Name | B20: Role | C20: School/COI
A21: Benjamin Wing | B21: Principal Investigator | C21: School of Engineering
A22: Zhu Taixiu | B22: Co-Principal Investigator | C22: School of Engineering
A23: Jaseema Banu | B23: Member | C23: School of Engineering
B24: Co-Principal Investigator | C24: Please select …
A26: EXTERNAL COLLABORATOR(S)
A28: Company Name | B28: UEN | C28: Company Type | D28: Contribution Cash $ | E28: Contribution In-Kind $ | F28: Remarks
A29: Infineon Technologies | B29: 197000667M | C29: MNC | D29: 0 | E29: 13100 | F29: Hardware and training
C30: Please select … | D30: 0 | E30: 0
C31: Please select … | D31: 0 | E31: 0
C32: Please select … | D32: 0 | E32: 0
A34: TECHNOLOGY READINESS LEVEL (TRL)
A36: TRL Level - Entry | B36: 0 - IDEA
A37: TRL Level - Exit | B37: 0 - IDEA
A40: * Relevant to NP Capability Development Grant
A42: ABSTRACT
A45: The widespread adoption of Lithium-Ion Batteries (LIBs) in Electric Vehicles (EVs) is impeded by safety risks, particularly thermal runaway. While battery management systems (BMSs) detect failures reactively, proactive prediction of thermal runaway remains a critical unmet need. This project aims to develop prognostic capabilities by leveraging cycling data—voltage, current, and temperature—to identify precursors to thermal runaway. Using a cycling chamber/tester, LIBs will undergo rigorous charge/discharge tests under unfavourable environmental conditions, including accelerated ageing and abusive loading, to induce degradation. A high-resolution time-series dataset will capture electrochemical evolution leading to failure. Machine learning models will analyse this data to detect subtle non-linear anomalies in voltage relaxation and internal resistance, enabling early prediction of thermal runaway. The outcomes include: (1) A comprehensive dataset linking cycling parameters to thermal runaway precursors, (2) A machine learning framework for early failure prediction, and (3) Integration of prognostic algorithms into BMS architectures to isolate at-risk cells pre-emptively. This work will enhance operational safety, mitigate catastrophic failures, and advance the reliability of LIBs in automotive applications. | I45: =LEN(TRIM(A45))-LEN(SUBSTITUTE(A45," ",""))+1 -> 167 | J45: Word Count
A47: Background IP
A48: As the objective of the RIE2025 grant is to develop commercial products, systems and applications using IP from the local universities, research institutes and Polytechnics and ITE, please be informed that applicants should not propose projects that use IPs created outside of Singapore.
A49: NA | I49: =LEN(TRIM(A49))-LEN(SUBSTITUTE(A49," ",""))+1 -> 1 | J49: Word Count
A51: Background IP
A52: If a company's background IP(s) is/are invovled, please provide the exact details. List down the patent reference number(s) if available.
A53: NA | I53: =LEN(TRIM(A53))-LEN(SUBSTITUTE(A53," ",""))+1 -> 1 | J53: Word Count
A55: SCOPE OF PROJECT
A58: The primary objective is to conduct rigorous testing to gather datasets for developing a predictive model capable of identifying early warning signs (precursors) of thermal runaway in lithium-ion cells before catastrophic failure occurs. The project will utilise controlled battery cycling to induce degradation and capture high-resolution electrochemical data for analysis, as elaborated below. i) Experimental Set-Up and Safety - Test Bench Construction: Set-up of battery cyclers (Chroma & NGI) and environmental chambers. - Sensor Integration: Installation of thermocouples, voltage sensors, and strain gauges (if monitoring swelling) on target cells. - Safety Protocols: Implementation of containment vessels and fire suppression systems to manage intentional or accidental thermal events during testing. ii) Data Generation (Cycling Regimes) - Baseline Characterisation: Perform initial capacity and impedance checks on fresh cells. - Accelerated Ageing: Subject cells to high C-rate cycling and elevated temperatures to accelerate degradation. - Abuse/Trigger Testing*: Apply controlled overcharge or overheating protocols to push cells toward the “onset” of thermal runaway, capturing near-failure data. *Constraint: Testing will cease immediately upon detection of thermal runaway initiation (venting or rapid temperature rise) to preserve data integrity. iii) Data Analysis and Modelling - Extract key features from raw battery data, such as coulombic efficiency trends, differential voltage analysis, and temperature rate of change. These will be used to develop machine learning learning models for predicting thermal runaway precursors. | I58: =LEN(TRIM(A58))-LEN(SUBSTITUTE(A58," ",""))+1 -> 213 | J58: Word Count
A59: References
A60: [1] “Analysis and key findings from real-world electric vehicle field data” (URL: https://doi.org/10.1016/j.joule.2023.07.018) [2] “A critical review of thermal runaway prediction and early-warning methods for lithium-ion batteries” (URL: https://doi.org/10.34133/energymatadv.0008) | I60: =LEN(TRIM(A60))-LEN(SUBSTITUTE(A60," ",""))+1 -> 28 | J60: Word Count
A62: PROJECT DELIVERABLES
...

Sheet Project Team - Timeline
A1: NP - Grant Management - Proposal Template ( August 25 ) 3.0
A3: Section 3 - Project Team & Time Line
A5: PROJECT TEAM (NP)
A6: PI & Co-PI's Name & School/COI auto-populate from Section 1 - Overview
A7: Role | B7: Salutation | C7: Name Auto populate for PI & Co-PI from Overview | F7: School / COI Auto-populate for PI & Co-PI from Overview | I7: Time Contribution No. of hours per week | K7: Auto-populate Project Duration Years | L7: Auto-Calculate Time Contribution Per Project Duration No. of hours | N7: Area of Expertise | R7: Major Responsibility and project contribution | U7: Projects Track Records
A8: Principal Investigator | B8: Mr | C8: =[2]Overview!A21 -> Benjamin Wing | F8: =Overview!C21 -> School of Engineering | I8: 3 | K8: =Overview!$B$15/12 -> 1.5 | L8: =I8*K8*52 -> 234 | N8: Power Electronics & Battery Testing | R8: Perform battery cycling and operation in the chamber
A9: Co-Principal Investigator | B9: Dr | C9: =[2]Overview!A22 -> Zhu Taixiu | F9: =Overview!C22 -> School of Engineering | I9: 3 | K9: =Overview!$B$15/12 -> 1.5 | L9: =I9*K9*52 -> 234 | N9: Sustainable energy management | R9: Data validation and system modelling
A10: Member | B10: Ms | C10: =[2]Overview!A23 -> Jaseema Banu | F10: =Overview!C23 -> School of Engineering | I10: 2 | K10: =Overview!$B$15/12 -> 1.5 | L10: =I10*K10*52 -> 156 | N10: System Modeling | R10: System modelling on MATLAB
A11: Co-Principal Investigator | B11: Mr | C11: =Overview!A24 -> 0 | F11: =Overview!C24 -> Please select … | I11: 0 | K11: =Overview!$B$15/12 -> 1.5 | L11: =I11*K11*52 -> 0
A12: Member | B12: Mr | F12: Please select … | I12: 0 | K12: =Overview!$B$15/12 -> 1.5 | L12: =I12*K12*52 -> 0
A13: Member | B13: Mr | F13: Please select … | I13: 0 | K13: =Overview!$B$15/12 -> 1.5 | L13: =I13*K13*52 -> 0
A14: Member | B14: Mr | F14: Please select … | I14: 0 | K14: =Overview!$B$15/12 -> 1.5 | L14: =I14*K14*52 -> 0
A15: Member | B15: Mr | F15: Please select … | I15: 0 | K15: =Overview!$B$15/12 -> 1.5 | L15: =I15*K15*52 -> 0
A16: Member | B16: Mr | F16: Please select … | I16: 0 | K16: =Overview!$B$15/12 -> 1.5 | L16: =I16*K16*52 -> 0
A18: EXTERNAL COLLABORATOR(S)
A19: Company name and type auto-populate from Section 1 - Overview For classification of Company Type, refer to NOTES page.
A20: Company Name Auto-populate from Overview | B20: Company Type Auto-populate from Overview | C20: Salutation | E20: Name | H20: Designation | N20: Area of Expertise | Q20: Collaborator Responsibility and project contribution
A21: =[2]Overview!A29 -> Infineon Technologies | B21: =[2]Overview!C29 -> MNC | C21: Dr | E21: Wesley Poh | H21: AI Application Engineer | N21: Applied AI and Energy Storage Systems | Q21: Project Lead
A22: =[2]Overview!A29 -> Infineon Technologies | B22: =[2]Overview!C29 -> MNC | C22: Mr | E22: Robert Tan | H22: System Architect | N22: Battery Management Systems | Q22: Technical Consultant
A23: =[2]Overview!A29 -> Infineon Technologies | B23: =[2]Overview!C29 -> MNC | C23: Mr | E23: Karun Kowsik | H23: System Application Engineering Intern | N23: Electrical and Electronic Engineering | Q23: Data collection and test engineering
A25: TIME LINE
A27: Project - Intermediate Milestones | C27: Year 1 | G27: Year 2
C28: Q1 | D28: Q2 | E28: Q3 | F28: Q4 | G28: Q1 | H28: Q2 | I28: Q3 | J28: Q4
A29: Experimental Set-Up and Safety
A30: Data Generation (Cycling Regimes)
A31: Data Analysis and Modelling
A32: Testing on Infineon hardware
A33: Preparation for Publications and Demonstation
A38: Collaborators - Intermediate Milestones | C38: Year 1 | G38: Year 2
C39: Q1 | D39: Q2 | E39: Q3 | F39: Q4 | G39: Q1 | H39: Q2 | I39: Q3 | J39: Q4
A40: Perform training and to students on hardware and modeling. Train every batch of students for each sem
A41: Data Generation (Cycling Regimes)
A42: Data Analysis and Modelling
A43: Testing on Infineon hardware
A44: Preparation for Publications and Demonstation
A49: Students - Intermediate Milestones | C49: Year 1 | G49: Year 2
C50: Q1 | D50: Q2 | E50: Q3 | F50: Q4 | G50: Q1 | H50: Q2 | I50: Q3 | J50: Q4
A51: Experimental Set-Up and Safety
A52: Data Generation (Cycling Regimes)
A53: Data Analysis and Modelling
...

Sheet Project Info
A1: NP - Grant Management - Proposal Template ( August 25 ) 3.0
A3: Section 4 - Project Information
A5: What is the idea of the project about and it's impact and significance ?
A6: Thermal runaway remains a significant barrier to the adoption of lithium-ion batteries (LIBs) in electric vehicles (EVs). Current battery management systems (BMSs) only react to failures—this project pioneers prognostic capabilities to predict thermal runaway before irreversible damage occurs. By identifying early warning signals in cycling data and integrating machine learning into the BMS, pre-emptive safety actions can be enabled. This breakthrough will mitigate catastrophic failures, enhance EV safety, and accelerate consumer confidence in sustainable transportation—directly supporting global decarbonisation goals. | K6: =LEN(TRIM(A6))-LEN(SUBSTITUTE(A6," ",""))+1 -> 79 | L6: Word Count
A8: The Commercial Problem and Opportunity. What are the field of application ?
A9: Thermal runaway poses a significant safety and financial risk in EVs, leading to recalls, reputational damage, and consumer hesitancy. This project addresses this by enabling early prediction of battery failures, reducing costly incidents and enhancing EV reliability. Applications span automotive, energy storage, and aerospace industries, where LIB safety is critical. By integrating prognostic algorithms into BMS, manufacturers can offer safer, more competitive products, unlocking market growth and accelerating the transition to sustainable transportation. | K9: =LEN(TRIM(A9))-LEN(SUBSTITUTE(A9," ",""))+1 -> 73 | L9: Word Count
A11: Users and Customers. Who are the potential licensees ?
A12: Potential licensees include EV manufacturers, battery producers, and BMS developers. Fleet operators and energy storage system providers also stand to benefit. By licensing prognostic algorithms, these stakeholders can enhance product safety, reduce warranty costs, and gain a competitive edge. Additionally, regulatory bodies and insurance companies may adopt these solutions to improve safety standards and risk assessments in the EV ecosystem. | K12: =LEN(TRIM(A12))-LEN(SUBSTITUTE(A12," ",""))+1 -> 60 | L12: Word Count
A14: What's your COMPETITIVE EDGES of your IDEA? - Describe your COMPETITIVE EDGES by identifying the key benefit and key differentiator. Compare them with your competitors.
A15: Our competitive edge lies in proactive thermal runaway prediction, unlike competitors who focus on reactive detection. By leveraging machine learning to analyse subtle anomalies in battery cycling data, we enable early intervention, reducing catastrophic failures. This contrasts with traditional BMS, which only responds to overt symptoms. Our solution integrates seamlessly into existing BMS architectures, offering a cost-effective, scalable safety enhancement that outperforms current diagnostic-only systems. | K15: =LEN(TRIM(A15))-LEN(SUBSTITUTE(A15," ",""))+1 -> 65 | L15: Word Count
A17: Describe the Technology Readiness Level of the project before and after.
A18: Pre-project: TRL 3 Proof of concept validation. Active R&D is initiated with analytical and laboratory studies. Demonstration of technical feasibility that are exercise with representative data. Post-project: TRL 7 System prototyping demonstration in operational environment. The system is at or near the scale of the operational system, with most functions available for demonstration and test. Well integrated with collateral and ancillary systems. Limited documentation available. | K18: =LEN(TRIM(A18))-LEN(SUBSTITUTE(A18," ",""))+1 -> 64 | L18: Word Count
A20: Who's on your TEAM? - Describe the strength of your team by referring to its skills, commitment and synergy.
A21: - Dr Wesley Poh: Specialises in applied AI and energy storage systems - Mr Robert Tan: Specialises in BMS - Mr Karun Kowsik: Test Engineering - Dr Zhu Taixiu: Specialises in Battery prediction modelling - Mr Benjamin Wing: Specialises in Battery Testing Methodologies - Ms Jaseema Banu: Specialises in Matlab Modelling | K21: =LEN(TRIM(A21))-LEN(SUBSTITUTE(A21," ",""))+1 -> 46 | L21: Word Count
A23: Describe the Novelty of your IDEA. Justify by IP and market scanning.
A24: Our novelty lies in combining cycling data analysis with machine learning to predict thermal runaway and precursors. Market scanning reveals no existing solutions offering such predictive capabilities. Patent-pending algorithms ensure IP protection, while our approach addresses a critical gap in battery safety, positioning us as pioneers in this space. | K24: =LEN(TRIM(A24))-LEN(SUBSTITUTE(A24," ",""))+1 -> 49 | L24: Word Count
A26: What's your PATH TO MARKET? - Describe your PATH TO MARKET by major initiatives, measure of success and timing to market for your idea.
A27: Major initiatives include: 1) Partnering with BMS developers for integration, 2) Licensing algorithms to EV manufacturers, and 3) Collaborating with regulatory bodies for adoption. Success will be measured by pilot deployments and licensing agreements. Timing to market: 18-24 months post-project completion, leveraging industry partnerships and validation testing. | K27: =LEN(TRIM(A27))-LEN(SUBSTITUTE(A27," ",""))+1 -> 47 | L27: Word Count
A29: Others
K30: =LEN(TRIM(A30))-LEN(SUBSTITUTE(A30," ",""))+1 -> 1 | L30: Word Count
A33: ~ End of Page ~

Sheet Declaration - Sign Off
A1: NP - Grant Management - Proposal Template ( August 25 ) 3.0
A3: Section 5 - Declaration & Sign-Off
A5: A. Declaration of Ethics Approval
A7: Ethics category | B7: Involved? If Yes, Please Declare Participating Institution where Research Requiring Ethics Approval will be Conducted. | C7: Ethics Approval Required? | D7: Ethics Approval Expiry Date | E7: Comments / Reasons
A8: Requirement for Containment | B8: Yes or No ? | C8: Yes or No ?
A9: Use of Animal Tissues or Cells | B9: Yes or No ? | C9: Yes or No ?
A10: Human Subject | B10: Yes or No ? | C10: Yes or No ?
A11: Requirement for containment Class 2 and above | B11: Yes or No ? | C11: Yes or No ?
A12: Use of Human Tissues or Cells | B12: Yes or No ? | C12: Yes or No ?
A13: Use of Human Tissues or Cells from Primary Donors (i.e. subject / volunteers recruited for project) | B13: Yes or No ? | C13: Yes or No ?
A14: Use of Commercially Available Human Material/Animal Tissues or Cells | B14: Yes or No ? | C14: Yes or No ?
A15: Multi-centre Trial(s) | B15: Yes or No ? | C15: Yes or No ?
A16: Animal Experimentation | B16: Yes or No ? | C16: Yes or No ?
A19: B. Undertaking by Lead PI
A21: In acknowledging this Grant Application, the Principal Investigator PI UNDERTAKE, on any Grant Award to: • Declare that all information is accurate and true. • Ensure that approval from the funding agency has been obtained before engaging in any commercial activity that will exploit the finds of the research funded by the funding agency • Read, support and agree to this proposal being carried out in the Institution • Be actively engaged in the execution of the research and ensure that the study complies with all laws, rules and regulations pertaining to animal and human ethics, including the Singapore Good Clinical Practice Guidelines • Not send similar versions or part(s) of this proposal to other agencies for funding. • For Biomedical Science proposal, submit supporting documents of ethics approval obtained from the relevant Institutional Review Board (IRB) and Animal Ethics Committee for studies involving human subjects/human tissues or cells, and animal/animal tissues or cells respectively. • Ensure that all necessary licenses and approvals have been obtained or are being sought • Ensure that funding agency is acknowledged in all publications. • Ensure that all publications arising from the research is forwarded to the funding agency. • Ensure that the requested equipment/resources are not funded by another agency or research proposal. • Ensure that there is a reasonable effort in accessing available equipment/resources within the Institution or elsewhere within Singapore. • Ensure that there is no financial conflict of interest • Adhere to the funding agency's Grants T&Cs / Funding Guidelines • Agree to hold primary responsibility for the responsible conduct of research, and shall abide and comply with the ethical, legal and professional standards relevant to research, in accordance to the research integrity policy of the Institution
A23: Name of PI | B23: Acknowledgement
A24: Benjamin Wing
A26: C. Undertaking by Director of Academic School / Centre of Lead PI
A28: In acknowledging this Grant Application, the Director of Academic School of the Principal Investigator UNDERTAKES, to: • reserve a royalty-free, irrevocable, worldwide, perpetual and non-exclusive right for the funding agency to use the intellectual property generated by the research for MOE's own non-commercial and R&D purposes. • support and agree to this proposal being carried out in the Department. • ensure that all necessary licenses and approvals have been obtained or are being sought.
A30: Name of Director of Academic School / Centre of Principal Investigator / Co-Principal Investigator | B30: Acknowledgement
A31: Tan Wei Lian
A33: Name of Director of Co-Principal Investigator from other Academic School / Centre | B33: Acknowledgement
A36: Name of Director of Co-Principal Investigator from other Academic School / Centre | B36: Acknowledgement
A39: Name of Director of Co-Principal Investigator from other Academic School / Centre | B39: Acknowledgement
A57: ~ End of Page ~

Sheet Contribution in-kind
B2: Contribution in-kind by Infineon (breakdown):
B3: Item | C3: Cost (S$)
B4: EIS demo (consisting of 1x AURIX TFT kit with PSOC-4 SPM, 2x TLE9018 evaluation board) | C4: 10000
B5: Knowledge transfer on the project (1 x E1 BMS training - 10hrs , 1x EIS demo training - 21 hrs) - Total 31 hrs | C5: 3100
